test_add_two_negative (class_1118_unittest.class_01.TestMathMethod) ... ok
test_add_two_positive (class_1118_unittest.class_01.TestMathMethod) ... ok
test_add_two_zero (class_1118_unittest.class_01.TestMathMethod) ... FAIL

======================================================================
FAIL: test_add_two_zero (class_1118_unittest.class_01.TestMathMethod)
----------------------------------------------------------------------
Traceback (most recent call last):
  File "C:\Users\haiyu.ma\PycharmProjects\lemon_class\class_1118_unittest\class_01.py", line 29, in test_add_two_zero
    self.assertEquals(1,res,"两个0相加出错了")#断言里面msg在用例执行失败的时候才会显示
AssertionError: 1 != 0 : 两个0相加出错了

----------------------------------------------------------------------
Ran 3 tests in 0.001s

FAILED (failures=1)
