2021-04-09 17:40:18,688-INFO-my_log.py-python-日志信息:开始执行用例：1--正常登录
2021-04-09 17:40:18,689-INFO-my_log.py-python-日志信息:获取到的请求数据是:{"username": "m", "password": "password.1"}
2021-04-09 17:40:18,958-INFO-my_log.py-python-日志信息:获取到的结果是：{'id_token': 'eyJhbGciOiJIUzUxMiJ9.eyJzdWIiOiJtIiwiYXV0aCI6IlJPTEVfQklPSU5GTyxST0xFX0NPTUJJTkVEX1RIRVJBUFlfUixST0xFX0NPTUJJTkVEX1RIRVJBUFlfVyxST0xFX0NSLFJPTEVfREVBVEhfQVBQUk9WRV9BLFJPTEVfREVBVEhfQVBQUk9WRV9SLFJPTEVfRElTRUFTRV9DT1VSU0VfQSxST0xFX0RJU0VBU0VfQ09VUlNFX1IsUk9MRV9ESVNFQVNFX0NPVVJTRV9TWU5DLFJPTEVfRElTRUFTRV9DT1VSU0VfVyxST0xFX0RJX0NVU1RPTUVSX1IsUk9MRV9ESV9DVVNUT01FUl9XLFJPTEVfRElfTUVESUNBTF9SRVNVTFRfUixST0xFX0RPQ1RPUl9SLFJPTEVfRE9DVE9SX1csUk9MRV9EUlVHX0RJQ1RJT05BUllfUixST0xFX0RSVUdfRElDVElPTkFSWV9XLFJPTEVfRU1QTE9ZRUVfVyxST0xFX0ZJTkFOQ0lBTF9SRVBPUlQsUk9MRV9GSU5BTkNJQUxfU0VUVExFTUVOVF9DLFJPTEVfRklOQU5DSUFMX1NFVFRMRU1FTlRfUixST0xFX0ZJTkFOQ0lBTF9TRVRUTEVNRU5UX1csUk9MRV9GT0xMT1dfVVBfQVRURU5USU9OX1QsUk9MRV9GT0xMT1dfVVBfQVRURU5USU9OX1csUk9MRV9GT0xMT1dfVVBfUkVDT1JEX1csUk9MRV9IT1NQSVRBTF9DT05GSVJNX0RFQVRIX0FQUFJPVkVfQSxST0xFX0hPU1BJVEFMX0NPTkZJUk1fREVBVEhfQVBQUk9WRV9SLFJPTEVfSE9TUElUQUxfUixST0xFX0hPU1BJVEFMX1csUk9MRV9NQVRFUklBTF9BLFJPTEVfTUFURVJJQUxfUixST0xFX01BVEVSSUFMX1JFUE9SVCxST0xFX01BVEVSSUFMX1csUk9MRV9NRURJQ0FMLFJPTEVfT1JERVJfQSxST0xFX09SREVSX0NBTkNFTCxST0xFX09SREVSX0NMT1NFLFJPTEVfT1JERVJfQ09ORklSTV9SRUNFSVBULFJPTEVfT1JERVJfUixST0xFX09SREVSX1JFRlVORCxST0xFX09SREVSX1csUk9MRV9QQVRJRU5UX0FERFJFU1NfUixST0xFX1BBVElFTlRfQUREUkVTU19XLFJPTEVfUEFUSUVOVF9EQVRBX0lOVEVHUklUWV9DT01QTEVURV9SRVBPUlQsUk9MRV9QQVRJRU5UX1IsUk9MRV9QQVRJRU5UX1JFUE9SVCxST0xFX1BBVElFTlRfVyxST0xFX1BSRV9PUkRFUl9SLFJPTEVfUFJPRFVDVF9SLFJPTEVfUFJPRFVDVF9XLFJPTEVfUFJPRFVDVF9XX0JBU0lDLFJPTEVfUFJPRFVDVF9XX1JFUE9SVF9GSUxFLFJPTEVfUFJPRFVDVF9XX1U4LFJPTEVfUVVBUlRFUl9SRVBPUlRfVyxST0xFX1JFUE9SVF9SLFJPTEVfUkVQT1JUX1csUk9MRV9SRVNFQVJDSF9DT05UUkFDVF9SLFJPTEVfUkVTRUFSQ0hfQ09OVFJBQ1RfVyxST0xFX1JFVklFV19XLFJPTEVfU0FMRSxST0xFX1RFTkFOVF9SLFJPTEVfVEVOQU5UX1csUk9MRV9USU1FTElORV9XLFJPTEVfVFJFQVRNRU5UX1csUk9MRV9VU0VSIiwiZXhwIjoxNjE4MDQ3NjE4fQ.gZ03ftR_zSrMwO4BOemDDc0FoGHI_IyM01L_ndUNEwrvIOkKqxQ96TrBelcqzBVBClpQbLRCeS1WMX81jcHb7Q'}
2021-04-09 17:40:18,959-INFO-my_log.py-python-日志信息:PASS
2021-04-09 17:40:18,960-INFO-my_log.py-python-日志信息:开始执行用例：2--密码错误
2021-04-09 17:40:18,960-INFO-my_log.py-python-日志信息:获取到的请求数据是:{"username": "m", "password": "12345678"}
2021-04-09 17:40:19,192-INFO-my_log.py-python-日志信息:获取到的结果是：{'AuthenticationException': 'Bad credentials'}
2021-04-09 17:40:19,193-INFO-my_log.py-python-日志信息:PASS
2021-04-09 17:40:19,195-INFO-my_log.py-python-日志信息:开始执行用例：3--密码为空
2021-04-09 17:40:19,196-INFO-my_log.py-python-日志信息:获取到的请求数据是:{"username": "m", "password": ""}
2021-04-09 17:40:19,296-INFO-my_log.py-python-日志信息:获取到的结果是：{'message': 'error.validation', 'description': None, 'fieldErrors': [{'objectName': 'loginVM', 'field': 'password', 'message': 'size must be between 4 and 100'}], 'params': None}
2021-04-09 17:40:19,296-INFO-my_log.py-python-日志信息:PASS
2021-04-09 17:40:19,297-INFO-my_log.py-python-日志信息:开始执行用例：4--账号错误
2021-04-09 17:40:19,299-INFO-my_log.py-python-日志信息:获取到的请求数据是:{"username": "qwwrty", "password": "password.1"}
2021-04-09 17:40:19,502-INFO-my_log.py-python-日志信息:获取到的结果是：{'AuthenticationException': 'Bad credentials'}
2021-04-09 17:40:19,503-INFO-my_log.py-python-日志信息:PASS
2021-04-09 17:40:19,503-INFO-my_log.py-python-日志信息:开始执行用例：5--账号为空
2021-04-09 17:40:19,504-INFO-my_log.py-python-日志信息:获取到的请求数据是:{"username": "", "password": "password.1"}
2021-04-09 17:40:19,601-INFO-my_log.py-python-日志信息:获取到的结果是：{'message': 'error.validation', 'description': None, 'fieldErrors': [{'objectName': 'loginVM', 'field': 'username', 'message': 'size must be between 1 and 50'}], 'params': None}
2021-04-09 17:40:19,603-INFO-my_log.py-python-日志信息:PASS
2021-04-09 17:40:19,604-INFO-my_log.py-python-日志信息:开始执行用例：6--账号密码全错
2021-04-09 17:40:19,605-INFO-my_log.py-python-日志信息:获取到的请求数据是:{"username": "qwwrty", "password": "password.3"}
2021-04-09 17:40:19,804-INFO-my_log.py-python-日志信息:获取到的结果是：{'AuthenticationException': 'Bad credentials'}
2021-04-09 17:40:19,806-INFO-my_log.py-python-日志信息:PASS
2021-04-09 17:40:19,807-INFO-my_log.py-python-日志信息:开始执行用例：7--账号密码全空
2021-04-09 17:40:19,808-INFO-my_log.py-python-日志信息:获取到的请求数据是:{"username": "", "password": ""}
2021-04-09 17:40:19,904-INFO-my_log.py-python-日志信息:获取到的结果是：{'message': 'error.validation', 'description': None, 'fieldErrors': [{'objectName': 'loginVM', 'field': 'username', 'message': 'size must be between 1 and 50'}, {'objectName': 'loginVM', 'field': 'password', 'message': 'size must be between 4 and 100'}], 'params': None}
2021-04-09 17:40:19,905-INFO-my_log.py-python-日志信息:PASS
2021-04-13 23:26:48,604-INFO-my_log.py-python-日志信息:开始执行用例：1--正常登录
2021-04-13 23:26:48,612-INFO-my_log.py-python-日志信息:获取到的请求数据是:{"username": "m", "password": "password.1"}
2021-04-13 23:27:09,812-ERROR-my_log.py-python-日志信息:请求报错了
2021-04-13 23:27:09,825-INFO-my_log.py-python-日志信息:开始执行用例：2--密码错误
2021-04-13 23:27:09,827-INFO-my_log.py-python-日志信息:获取到的请求数据是:{"username": "m", "password": "12345678"}
2021-04-13 23:27:30,833-ERROR-my_log.py-python-日志信息:请求报错了
2021-04-13 23:27:30,839-INFO-my_log.py-python-日志信息:开始执行用例：3--密码为空
2021-04-13 23:27:30,841-INFO-my_log.py-python-日志信息:获取到的请求数据是:{"username": "m", "password": ""}
2021-04-13 23:27:51,858-ERROR-my_log.py-python-日志信息:请求报错了
2021-04-13 23:27:51,865-INFO-my_log.py-python-日志信息:开始执行用例：4--账号错误
2021-04-13 23:27:51,871-INFO-my_log.py-python-日志信息:获取到的请求数据是:{"username": "qwwrty", "password": "password.1"}
2021-04-13 23:28:12,873-ERROR-my_log.py-python-日志信息:请求报错了
2021-04-13 23:28:12,878-INFO-my_log.py-python-日志信息:开始执行用例：5--账号为空
2021-04-13 23:28:12,881-INFO-my_log.py-python-日志信息:获取到的请求数据是:{"username": "", "password": "password.1"}
2021-04-13 23:28:33,891-ERROR-my_log.py-python-日志信息:请求报错了
2021-04-13 23:28:33,907-INFO-my_log.py-python-日志信息:开始执行用例：6--账号密码全错
2021-04-13 23:28:33,915-INFO-my_log.py-python-日志信息:获取到的请求数据是:{"username": "qwwrty", "password": "password.3"}
2021-04-13 23:28:54,921-ERROR-my_log.py-python-日志信息:请求报错了
2021-04-13 23:28:54,924-INFO-my_log.py-python-日志信息:开始执行用例：7--账号密码全空
2021-04-13 23:28:54,926-INFO-my_log.py-python-日志信息:获取到的请求数据是:{"username": "", "password": ""}
2021-04-13 23:29:15,928-ERROR-my_log.py-python-日志信息:请求报错了
2021-04-14 14:30:32,654-INFO-my_log.py-python-日志信息:开始执行用例：1--正常登录
2021-04-14 14:30:32,660-INFO-my_log.py-python-日志信息:获取到的请求数据是:{"username": "m", "password": "password.1"}
2021-04-14 14:30:33,060-INFO-my_log.py-python-日志信息:获取到的结果是：{'id_token': 'eyJhbGciOiJIUzUxMiJ9.eyJzdWIiOiJtIiwiYXV0aCI6IlJPTEVfQklPSU5GTyxST0xFX0NPTUJJTkVEX1RIRVJBUFlfUixST0xFX0NPTUJJTkVEX1RIRVJBUFlfVyxST0xFX0NSLFJPTEVfREVBVEhfQVBQUk9WRV9BLFJPTEVfREVBVEhfQVBQUk9WRV9SLFJPTEVfRElTRUFTRV9DT1VSU0VfQSxST0xFX0RJU0VBU0VfQ09VUlNFX1IsUk9MRV9ESVNFQVNFX0NPVVJTRV9TWU5DLFJPTEVfRElTRUFTRV9DT1VSU0VfVyxST0xFX0RJX0NVU1RPTUVSX1IsUk9MRV9ESV9DVVNUT01FUl9XLFJPTEVfRElfTUVESUNBTF9SRVNVTFRfUixST0xFX0RPQ1RPUl9SLFJPTEVfRE9DVE9SX1csUk9MRV9EUlVHX0RJQ1RJT05BUllfUixST0xFX0RSVUdfRElDVElPTkFSWV9XLFJPTEVfRU1QTE9ZRUVfVyxST0xFX0ZJTkFOQ0lBTF9SRVBPUlQsUk9MRV9GSU5BTkNJQUxfU0VUVExFTUVOVF9DLFJPTEVfRklOQU5DSUFMX1NFVFRMRU1FTlRfUixST0xFX0ZJTkFOQ0lBTF9TRVRUTEVNRU5UX1csUk9MRV9GT0xMT1dfVVBfQVRURU5USU9OX1QsUk9MRV9GT0xMT1dfVVBfQVRURU5USU9OX1csUk9MRV9GT0xMT1dfVVBfUkVDT1JEX1csUk9MRV9IT1NQSVRBTF9DT05GSVJNX0RFQVRIX0FQUFJPVkVfQSxST0xFX0hPU1BJVEFMX0NPTkZJUk1fREVBVEhfQVBQUk9WRV9SLFJPTEVfSE9TUElUQUxfUixST0xFX0hPU1BJVEFMX1csUk9MRV9NQVRFUklBTF9BLFJPTEVfTUFURVJJQUxfUixST0xFX01BVEVSSUFMX1JFUE9SVCxST0xFX01BVEVSSUFMX1csUk9MRV9NRURJQ0FMLFJPTEVfT1JERVJfQSxST0xFX09SREVSX0NBTkNFTCxST0xFX09SREVSX0NMT1NFLFJPTEVfT1JERVJfQ09ORklSTV9SRUNFSVBULFJPTEVfT1JERVJfUixST0xFX09SREVSX1JFRlVORCxST0xFX09SREVSX1csUk9MRV9QQVRJRU5UX0FERFJFU1NfUixST0xFX1BBVElFTlRfQUREUkVTU19XLFJPTEVfUEFUSUVOVF9EQVRBX0lOVEVHUklUWV9DT01QTEVURV9SRVBPUlQsUk9MRV9QQVRJRU5UX1IsUk9MRV9QQVRJRU5UX1JFUE9SVCxST0xFX1BBVElFTlRfVyxST0xFX1BSRV9PUkRFUl9SLFJPTEVfUFJPRFVDVF9SLFJPTEVfUFJPRFVDVF9XLFJPTEVfUFJPRFVDVF9XX0JBU0lDLFJPTEVfUFJPRFVDVF9XX1JFUE9SVF9GSUxFLFJPTEVfUFJPRFVDVF9XX1U4LFJPTEVfUVVBUlRFUl9SRVBPUlRfVyxST0xFX1JFUE9SVF9SLFJPTEVfUkVQT1JUX1csUk9MRV9SRVNFQVJDSF9DT05UUkFDVF9SLFJPTEVfUkVTRUFSQ0hfQ09OVFJBQ1RfVyxST0xFX1JFVklFV19XLFJPTEVfU0FMRSxST0xFX1RFTkFOVF9SLFJPTEVfVEVOQU5UX1csUk9MRV9USU1FTElORV9XLFJPTEVfVFJFQVRNRU5UX1csUk9MRV9VU0VSIiwiZXhwIjoxNjE4NDY4MjMyfQ.bzf08J3dsNMvpCnXa-N0cAM3gily884WUcNH2H8gZSwHdAwhjrgLXfK2axqyCUWUtM0oiXIASUlsYN6Am1rRbQ'}
2021-04-14 14:30:33,061-INFO-my_log.py-python-日志信息:PASS
2021-04-14 14:30:33,061-INFO-my_log.py-python-日志信息:开始执行用例：2--密码错误
2021-04-14 14:30:33,062-INFO-my_log.py-python-日志信息:获取到的请求数据是:{"username": "m", "password": "12345678"}
2021-04-14 14:30:33,299-INFO-my_log.py-python-日志信息:获取到的结果是：{'AuthenticationException': 'Bad credentials'}
2021-04-14 14:30:33,300-INFO-my_log.py-python-日志信息:PASS
2021-04-14 14:30:33,301-INFO-my_log.py-python-日志信息:开始执行用例：3--密码为空
2021-04-14 14:30:33,302-INFO-my_log.py-python-日志信息:获取到的请求数据是:{"username": "m", "password": ""}
2021-04-14 14:30:33,417-INFO-my_log.py-python-日志信息:获取到的结果是：{'message': 'error.validation', 'description': None, 'fieldErrors': [{'objectName': 'loginVM', 'field': 'password', 'message': 'size must be between 4 and 100'}], 'params': None}
2021-04-14 14:30:33,418-INFO-my_log.py-python-日志信息:PASS
2021-04-14 14:30:33,419-INFO-my_log.py-python-日志信息:开始执行用例：4--账号错误
2021-04-14 14:30:33,420-INFO-my_log.py-python-日志信息:获取到的请求数据是:{"username": "qwwrty", "password": "password.1"}
2021-04-14 14:30:33,638-INFO-my_log.py-python-日志信息:获取到的结果是：{'AuthenticationException': 'Bad credentials'}
2021-04-14 14:30:33,639-INFO-my_log.py-python-日志信息:PASS
2021-04-14 14:30:33,640-INFO-my_log.py-python-日志信息:开始执行用例：5--账号为空
2021-04-14 14:30:33,641-INFO-my_log.py-python-日志信息:获取到的请求数据是:{"username": "", "password": "password.1"}
2021-04-14 14:30:33,777-INFO-my_log.py-python-日志信息:获取到的结果是：{'message': 'error.validation', 'description': None, 'fieldErrors': [{'objectName': 'loginVM', 'field': 'username', 'message': 'size must be between 1 and 50'}], 'params': None}
2021-04-14 14:30:33,778-INFO-my_log.py-python-日志信息:PASS
2021-04-14 14:30:33,779-INFO-my_log.py-python-日志信息:开始执行用例：6--账号密码全错
2021-04-14 14:30:33,780-INFO-my_log.py-python-日志信息:获取到的请求数据是:{"username": "qwwrty", "password": "password.3"}
2021-04-14 14:30:34,100-INFO-my_log.py-python-日志信息:获取到的结果是：{'AuthenticationException': 'Bad credentials'}
2021-04-14 14:30:34,101-INFO-my_log.py-python-日志信息:PASS
2021-04-14 14:30:34,102-INFO-my_log.py-python-日志信息:开始执行用例：7--账号密码全空
2021-04-14 14:30:34,103-INFO-my_log.py-python-日志信息:获取到的请求数据是:{"username": "", "password": ""}
2021-04-14 14:30:34,201-INFO-my_log.py-python-日志信息:获取到的结果是：{'message': 'error.validation', 'description': None, 'fieldErrors': [{'objectName': 'loginVM', 'field': 'password', 'message': 'size must be between 4 and 100'}, {'objectName': 'loginVM', 'field': 'username', 'message': 'size must be between 1 and 50'}], 'params': None}
2021-04-14 14:30:34,202-INFO-my_log.py-python-日志信息:PASS
2021-04-14 14:31:58,804-INFO-my_log.py-python-日志信息:开始执行用例：1--正常登录
2021-04-14 14:31:58,817-INFO-my_log.py-python-日志信息:获取到的请求数据是:{"username": "m", "password": "password.1"}
2021-04-14 14:31:59,091-INFO-my_log.py-python-日志信息:获取到的结果是：{'id_token': 'eyJhbGciOiJIUzUxMiJ9.eyJzdWIiOiJtIiwiYXV0aCI6IlJPTEVfQklPSU5GTyxST0xFX0NPTUJJTkVEX1RIRVJBUFlfUixST0xFX0NPTUJJTkVEX1RIRVJBUFlfVyxST0xFX0NSLFJPTEVfREVBVEhfQVBQUk9WRV9BLFJPTEVfREVBVEhfQVBQUk9WRV9SLFJPTEVfRElTRUFTRV9DT1VSU0VfQSxST0xFX0RJU0VBU0VfQ09VUlNFX1IsUk9MRV9ESVNFQVNFX0NPVVJTRV9TWU5DLFJPTEVfRElTRUFTRV9DT1VSU0VfVyxST0xFX0RJX0NVU1RPTUVSX1IsUk9MRV9ESV9DVVNUT01FUl9XLFJPTEVfRElfTUVESUNBTF9SRVNVTFRfUixST0xFX0RPQ1RPUl9SLFJPTEVfRE9DVE9SX1csUk9MRV9EUlVHX0RJQ1RJT05BUllfUixST0xFX0RSVUdfRElDVElPTkFSWV9XLFJPTEVfRU1QTE9ZRUVfVyxST0xFX0ZJTkFOQ0lBTF9SRVBPUlQsUk9MRV9GSU5BTkNJQUxfU0VUVExFTUVOVF9DLFJPTEVfRklOQU5DSUFMX1NFVFRMRU1FTlRfUixST0xFX0ZJTkFOQ0lBTF9TRVRUTEVNRU5UX1csUk9MRV9GT0xMT1dfVVBfQVRURU5USU9OX1QsUk9MRV9GT0xMT1dfVVBfQVRURU5USU9OX1csUk9MRV9GT0xMT1dfVVBfUkVDT1JEX1csUk9MRV9IT1NQSVRBTF9DT05GSVJNX0RFQVRIX0FQUFJPVkVfQSxST0xFX0hPU1BJVEFMX0NPTkZJUk1fREVBVEhfQVBQUk9WRV9SLFJPTEVfSE9TUElUQUxfUixST0xFX0hPU1BJVEFMX1csUk9MRV9NQVRFUklBTF9BLFJPTEVfTUFURVJJQUxfUixST0xFX01BVEVSSUFMX1JFUE9SVCxST0xFX01BVEVSSUFMX1csUk9MRV9NRURJQ0FMLFJPTEVfT1JERVJfQSxST0xFX09SREVSX0NBTkNFTCxST0xFX09SREVSX0NMT1NFLFJPTEVfT1JERVJfQ09ORklSTV9SRUNFSVBULFJPTEVfT1JERVJfUixST0xFX09SREVSX1JFRlVORCxST0xFX09SREVSX1csUk9MRV9QQVRJRU5UX0FERFJFU1NfUixST0xFX1BBVElFTlRfQUREUkVTU19XLFJPTEVfUEFUSUVOVF9EQVRBX0lOVEVHUklUWV9DT01QTEVURV9SRVBPUlQsUk9MRV9QQVRJRU5UX1IsUk9MRV9QQVRJRU5UX1JFUE9SVCxST0xFX1BBVElFTlRfVyxST0xFX1BSRV9PUkRFUl9SLFJPTEVfUFJPRFVDVF9SLFJPTEVfUFJPRFVDVF9XLFJPTEVfUFJPRFVDVF9XX0JBU0lDLFJPTEVfUFJPRFVDVF9XX1JFUE9SVF9GSUxFLFJPTEVfUFJPRFVDVF9XX1U4LFJPTEVfUVVBUlRFUl9SRVBPUlRfVyxST0xFX1JFUE9SVF9SLFJPTEVfUkVQT1JUX1csUk9MRV9SRVNFQVJDSF9DT05UUkFDVF9SLFJPTEVfUkVTRUFSQ0hfQ09OVFJBQ1RfVyxST0xFX1JFVklFV19XLFJPTEVfU0FMRSxST0xFX1RFTkFOVF9SLFJPTEVfVEVOQU5UX1csUk9MRV9USU1FTElORV9XLFJPTEVfVFJFQVRNRU5UX1csUk9MRV9VU0VSIiwiZXhwIjoxNjE4NDY4MzE5fQ.SmLbV-eVMAKqNAmzQlxqKSSO6tvGNYyFq1BK53Mx755FJCWkCDjkTLLvhcrJsYyoR4B_nOjUty-oG9SjC6GnQA'}
2021-04-14 14:31:59,092-INFO-my_log.py-python-日志信息:PASS
2021-04-14 14:31:59,094-INFO-my_log.py-python-日志信息:开始执行用例：2--密码错误
2021-04-14 14:31:59,095-INFO-my_log.py-python-日志信息:获取到的请求数据是:{"username": "m", "password": "12345678"}
2021-04-14 14:31:59,318-INFO-my_log.py-python-日志信息:获取到的结果是：{'AuthenticationException': 'Bad credentials'}
2021-04-14 14:31:59,320-INFO-my_log.py-python-日志信息:PASS
2021-04-14 14:31:59,321-INFO-my_log.py-python-日志信息:开始执行用例：3--密码为空
2021-04-14 14:31:59,322-INFO-my_log.py-python-日志信息:获取到的请求数据是:{"username": "m", "password": ""}
2021-04-14 14:31:59,413-INFO-my_log.py-python-日志信息:获取到的结果是：{'message': 'error.validation', 'description': None, 'fieldErrors': [{'objectName': 'loginVM', 'field': 'password', 'message': 'size must be between 4 and 100'}], 'params': None}
2021-04-14 14:31:59,414-INFO-my_log.py-python-日志信息:PASS
2021-04-14 14:31:59,415-INFO-my_log.py-python-日志信息:开始执行用例：4--账号错误
2021-04-14 14:31:59,416-INFO-my_log.py-python-日志信息:获取到的请求数据是:{"username": "qwwrty", "password": "password.1"}
2021-04-14 14:31:59,715-INFO-my_log.py-python-日志信息:获取到的结果是：{'AuthenticationException': 'Bad credentials'}
2021-04-14 14:31:59,716-INFO-my_log.py-python-日志信息:PASS
2021-04-14 14:31:59,717-INFO-my_log.py-python-日志信息:开始执行用例：5--账号为空
2021-04-14 14:31:59,719-INFO-my_log.py-python-日志信息:获取到的请求数据是:{"username": "", "password": "password.1"}
2021-04-14 14:31:59,815-INFO-my_log.py-python-日志信息:获取到的结果是：{'message': 'error.validation', 'description': None, 'fieldErrors': [{'objectName': 'loginVM', 'field': 'username', 'message': 'size must be between 1 and 50'}], 'params': None}
2021-04-14 14:31:59,816-INFO-my_log.py-python-日志信息:PASS
2021-04-14 14:31:59,818-INFO-my_log.py-python-日志信息:开始执行用例：6--账号密码全错
2021-04-14 14:31:59,819-INFO-my_log.py-python-日志信息:获取到的请求数据是:{"username": "qwwrty", "password": "password.3"}
2021-04-14 14:32:00,055-INFO-my_log.py-python-日志信息:获取到的结果是：{'AuthenticationException': 'Bad credentials'}
2021-04-14 14:32:00,056-INFO-my_log.py-python-日志信息:PASS
2021-04-14 14:32:00,057-INFO-my_log.py-python-日志信息:开始执行用例：7--账号密码全空
2021-04-14 14:32:00,058-INFO-my_log.py-python-日志信息:获取到的请求数据是:{"username": "", "password": ""}
2021-04-14 14:32:00,153-INFO-my_log.py-python-日志信息:获取到的结果是：{'message': 'error.validation', 'description': None, 'fieldErrors': [{'objectName': 'loginVM', 'field': 'username', 'message': 'size must be between 1 and 50'}, {'objectName': 'loginVM', 'field': 'password', 'message': 'size must be between 4 and 100'}], 'params': None}
2021-04-14 14:32:00,153-INFO-my_log.py-python-日志信息:PASS
2021-04-14 17:06:20,348-INFO-my_log.py-python-日志信息:开始执行用例：1--正常登录
2021-04-14 17:06:20,349-INFO-my_log.py-python-日志信息:获取到的请求数据是:{"username": "m", "password": "password.1"}
2021-04-14 17:06:20,710-INFO-my_log.py-python-日志信息:获取到的结果是：{'id_token': 'eyJhbGciOiJIUzUxMiJ9.eyJzdWIiOiJtIiwiYXV0aCI6IlJPTEVfQklPSU5GTyxST0xFX0NPTUJJTkVEX1RIRVJBUFlfUixST0xFX0NPTUJJTkVEX1RIRVJBUFlfVyxST0xFX0NSLFJPTEVfREVBVEhfQVBQUk9WRV9BLFJPTEVfREVBVEhfQVBQUk9WRV9SLFJPTEVfRElTRUFTRV9DT1VSU0VfQSxST0xFX0RJU0VBU0VfQ09VUlNFX1IsUk9MRV9ESVNFQVNFX0NPVVJTRV9TWU5DLFJPTEVfRElTRUFTRV9DT1VSU0VfVyxST0xFX0RJX0NVU1RPTUVSX1IsUk9MRV9ESV9DVVNUT01FUl9XLFJPTEVfRElfTUVESUNBTF9SRVNVTFRfUixST0xFX0RPQ1RPUl9SLFJPTEVfRE9DVE9SX1csUk9MRV9EUlVHX0RJQ1RJT05BUllfUixST0xFX0RSVUdfRElDVElPTkFSWV9XLFJPTEVfRU1QTE9ZRUVfVyxST0xFX0ZJTkFOQ0lBTF9SRVBPUlQsUk9MRV9GSU5BTkNJQUxfU0VUVExFTUVOVF9DLFJPTEVfRklOQU5DSUFMX1NFVFRMRU1FTlRfUixST0xFX0ZJTkFOQ0lBTF9TRVRUTEVNRU5UX1csUk9MRV9GT0xMT1dfVVBfQVRURU5USU9OX1QsUk9MRV9GT0xMT1dfVVBfQVRURU5USU9OX1csUk9MRV9GT0xMT1dfVVBfUkVDT1JEX1csUk9MRV9IT1NQSVRBTF9DT05GSVJNX0RFQVRIX0FQUFJPVkVfQSxST0xFX0hPU1BJVEFMX0NPTkZJUk1fREVBVEhfQVBQUk9WRV9SLFJPTEVfSE9TUElUQUxfUixST0xFX0hPU1BJVEFMX1csUk9MRV9NQVRFUklBTF9BLFJPTEVfTUFURVJJQUxfUixST0xFX01BVEVSSUFMX1JFUE9SVCxST0xFX01BVEVSSUFMX1csUk9MRV9NRURJQ0FMLFJPTEVfT1JERVJfQSxST0xFX09SREVSX0NBTkNFTCxST0xFX09SREVSX0NMT1NFLFJPTEVfT1JERVJfQ09ORklSTV9SRUNFSVBULFJPTEVfT1JERVJfUixST0xFX09SREVSX1JFRlVORCxST0xFX09SREVSX1csUk9MRV9QQVRJRU5UX0FERFJFU1NfUixST0xFX1BBVElFTlRfQUREUkVTU19XLFJPTEVfUEFUSUVOVF9EQVRBX0lOVEVHUklUWV9DT01QTEVURV9SRVBPUlQsUk9MRV9QQVRJRU5UX1IsUk9MRV9QQVRJRU5UX1JFUE9SVCxST0xFX1BBVElFTlRfVyxST0xFX1BSRV9PUkRFUl9SLFJPTEVfUFJPRFVDVF9SLFJPTEVfUFJPRFVDVF9XLFJPTEVfUFJPRFVDVF9XX0JBU0lDLFJPTEVfUFJPRFVDVF9XX1JFUE9SVF9GSUxFLFJPTEVfUFJPRFVDVF9XX1U4LFJPTEVfUVVBUlRFUl9SRVBPUlRfVyxST0xFX1JFUE9SVF9SLFJPTEVfUkVQT1JUX1csUk9MRV9SRVNFQVJDSF9DT05UUkFDVF9SLFJPTEVfUkVTRUFSQ0hfQ09OVFJBQ1RfVyxST0xFX1JFVklFV19XLFJPTEVfU0FMRSxST0xFX1RFTkFOVF9SLFJPTEVfVEVOQU5UX1csUk9MRV9USU1FTElORV9XLFJPTEVfVFJFQVRNRU5UX1csUk9MRV9VU0VSIiwiZXhwIjoxNjE4NDc3NTgwfQ.HVou1Ke7aH1dlc_OJ7q1Hjz9SlAKDC8WkDgw3TqbJQrpN-yiWleLds5VW9lVjcdBmMzs-WrOGIcbXNh9j-QZVg'}
2021-04-14 17:06:20,711-INFO-my_log.py-python-日志信息:PASS
2021-04-14 17:06:20,712-INFO-my_log.py-python-日志信息:开始执行用例：2--密码错误
2021-04-14 17:06:20,713-INFO-my_log.py-python-日志信息:获取到的请求数据是:{"username": "m", "password": "12345678"}
2021-04-14 17:06:20,927-INFO-my_log.py-python-日志信息:获取到的结果是：{'AuthenticationException': 'Bad credentials'}
2021-04-14 17:06:20,928-INFO-my_log.py-python-日志信息:PASS
2021-04-14 17:06:20,929-INFO-my_log.py-python-日志信息:开始执行用例：3--密码为空
2021-04-14 17:06:20,930-INFO-my_log.py-python-日志信息:获取到的请求数据是:{"username": "m", "password": ""}
2021-04-14 17:06:21,041-INFO-my_log.py-python-日志信息:获取到的结果是：{'message': 'error.validation', 'description': None, 'fieldErrors': [{'objectName': 'loginVM', 'field': 'password', 'message': 'size must be between 4 and 100'}], 'params': None}
2021-04-14 17:06:21,041-INFO-my_log.py-python-日志信息:PASS
2021-04-14 17:06:21,042-INFO-my_log.py-python-日志信息:开始执行用例：4--账号错误
2021-04-14 17:06:21,043-INFO-my_log.py-python-日志信息:获取到的请求数据是:{"username": "qwwrty", "password": "password.1"}
2021-04-14 17:06:21,240-INFO-my_log.py-python-日志信息:获取到的结果是：{'AuthenticationException': 'Bad credentials'}
2021-04-14 17:06:21,241-INFO-my_log.py-python-日志信息:PASS
2021-04-14 17:06:21,242-INFO-my_log.py-python-日志信息:开始执行用例：5--账号为空
2021-04-14 17:06:21,243-INFO-my_log.py-python-日志信息:获取到的请求数据是:{"username": "", "password": "password.1"}
2021-04-14 17:06:21,339-INFO-my_log.py-python-日志信息:获取到的结果是：{'message': 'error.validation', 'description': None, 'fieldErrors': [{'objectName': 'loginVM', 'field': 'username', 'message': 'size must be between 1 and 50'}], 'params': None}
2021-04-14 17:06:21,340-INFO-my_log.py-python-日志信息:PASS
2021-04-14 17:06:21,341-INFO-my_log.py-python-日志信息:开始执行用例：6--账号密码全错
2021-04-14 17:06:21,342-INFO-my_log.py-python-日志信息:获取到的请求数据是:{"username": "qwwrty", "password": "password.3"}
2021-04-14 17:06:21,564-INFO-my_log.py-python-日志信息:获取到的结果是：{'AuthenticationException': 'Bad credentials'}
2021-04-14 17:06:21,565-INFO-my_log.py-python-日志信息:PASS
2021-04-14 17:06:21,566-INFO-my_log.py-python-日志信息:开始执行用例：7--账号密码全空
2021-04-14 17:06:21,567-INFO-my_log.py-python-日志信息:获取到的请求数据是:{"username": "", "password": ""}
2021-04-14 17:06:21,664-INFO-my_log.py-python-日志信息:获取到的结果是：{'message': 'error.validation', 'description': None, 'fieldErrors': [{'objectName': 'loginVM', 'field': 'username', 'message': 'size must be between 1 and 50'}, {'objectName': 'loginVM', 'field': 'password', 'message': 'size must be between 4 and 100'}], 'params': None}
2021-04-14 17:06:21,665-INFO-my_log.py-python-日志信息:PASS
2021-04-15 09:50:33,391-INFO-my_log.py-python-日志信息:开始执行用例：1--正常登录
2021-04-15 09:50:33,392-INFO-my_log.py-python-日志信息:获取到的请求数据是:{"username": "m", "password": "password.1"}
2021-04-15 09:50:35,385-INFO-my_log.py-python-日志信息:获取到的结果是：{'id_token': 'eyJhbGciOiJIUzUxMiJ9.eyJzdWIiOiJtIiwiYXV0aCI6IlJPTEVfQklPSU5GTyxST0xFX0NPTUJJTkVEX1RIRVJBUFlfUixST0xFX0NPTUJJTkVEX1RIRVJBUFlfVyxST0xFX0NSLFJPTEVfREVBVEhfQVBQUk9WRV9BLFJPTEVfREVBVEhfQVBQUk9WRV9SLFJPTEVfRElTRUFTRV9DT1VSU0VfQSxST0xFX0RJU0VBU0VfQ09VUlNFX1IsUk9MRV9ESVNFQVNFX0NPVVJTRV9TWU5DLFJPTEVfRElTRUFTRV9DT1VSU0VfVyxST0xFX0RJX0NVU1RPTUVSX1IsUk9MRV9ESV9DVVNUT01FUl9XLFJPTEVfRElfTUVESUNBTF9SRVNVTFRfUixST0xFX0RPQ1RPUl9SLFJPTEVfRE9DVE9SX1csUk9MRV9EUlVHX0RJQ1RJT05BUllfUixST0xFX0RSVUdfRElDVElPTkFSWV9XLFJPTEVfRU1QTE9ZRUVfVyxST0xFX0ZJTkFOQ0lBTF9SRVBPUlQsUk9MRV9GSU5BTkNJQUxfU0VUVExFTUVOVF9DLFJPTEVfRklOQU5DSUFMX1NFVFRMRU1FTlRfUixST0xFX0ZJTkFOQ0lBTF9TRVRUTEVNRU5UX1csUk9MRV9GT0xMT1dfVVBfQVRURU5USU9OX1QsUk9MRV9GT0xMT1dfVVBfQVRURU5USU9OX1csUk9MRV9GT0xMT1dfVVBfUkVDT1JEX1csUk9MRV9IT1NQSVRBTF9DT05GSVJNX0RFQVRIX0FQUFJPVkVfQSxST0xFX0hPU1BJVEFMX0NPTkZJUk1fREVBVEhfQVBQUk9WRV9SLFJPTEVfSE9TUElUQUxfUixST0xFX0hPU1BJVEFMX1csUk9MRV9NQVRFUklBTF9BLFJPTEVfTUFURVJJQUxfUixST0xFX01BVEVSSUFMX1JFUE9SVCxST0xFX01BVEVSSUFMX1csUk9MRV9NRURJQ0FMLFJPTEVfT1JERVJfQSxST0xFX09SREVSX0NBTkNFTCxST0xFX09SREVSX0NMT1NFLFJPTEVfT1JERVJfQ09ORklSTV9SRUNFSVBULFJPTEVfT1JERVJfUixST0xFX09SREVSX1JFRlVORCxST0xFX09SREVSX1csUk9MRV9QQVRJRU5UX0FERFJFU1NfUixST0xFX1BBVElFTlRfQUREUkVTU19XLFJPTEVfUEFUSUVOVF9EQVRBX0lOVEVHUklUWV9DT01QTEVURV9SRVBPUlQsUk9MRV9QQVRJRU5UX1IsUk9MRV9QQVRJRU5UX1JFUE9SVCxST0xFX1BBVElFTlRfVyxST0xFX1BSRV9PUkRFUl9SLFJPTEVfUFJPRFVDVF9SLFJPTEVfUFJPRFVDVF9XLFJPTEVfUFJPRFVDVF9XX0JBU0lDLFJPTEVfUFJPRFVDVF9XX1JFUE9SVF9GSUxFLFJPTEVfUFJPRFVDVF9XX1U4LFJPTEVfUVVBUlRFUl9SRVBPUlRfVyxST0xFX1JFUE9SVF9SLFJPTEVfUkVQT1JUX1csUk9MRV9SRVNFQVJDSF9DT05UUkFDVF9SLFJPTEVfUkVTRUFSQ0hfQ09OVFJBQ1RfVyxST0xFX1JFVklFV19XLFJPTEVfU0FMRSxST0xFX1RFTkFOVF9SLFJPTEVfVEVOQU5UX1csUk9MRV9USU1FTElORV9XLFJPTEVfVFJFQVRNRU5UX1csUk9MRV9VU0VSIiwiZXhwIjoxNjE4NTM3ODM0fQ.p-7ln2-QrN7vfeTntWybE74SmhwlzmAyKHVJ2sJYMUMd1XirhALBn8pnXhVBgGOHZ21WQ_EcAUJIiAUOmnCtmg'}
2021-04-15 09:50:35,386-INFO-my_log.py-python-日志信息:PASS
2021-04-15 09:50:35,387-INFO-my_log.py-python-日志信息:开始执行用例：2--密码错误
2021-04-15 09:50:35,388-INFO-my_log.py-python-日志信息:获取到的请求数据是:{"username": "m", "password": "12345678"}
2021-04-15 09:50:35,812-INFO-my_log.py-python-日志信息:获取到的结果是：{'AuthenticationException': 'Bad credentials'}
2021-04-15 09:50:35,813-INFO-my_log.py-python-日志信息:PASS
2021-04-15 09:50:35,814-INFO-my_log.py-python-日志信息:开始执行用例：3--密码为空
2021-04-15 09:50:35,814-INFO-my_log.py-python-日志信息:获取到的请求数据是:{"username": "m", "password": ""}
2021-04-15 09:50:36,092-INFO-my_log.py-python-日志信息:获取到的结果是：{'message': 'error.validation', 'description': None, 'fieldErrors': [{'objectName': 'loginVM', 'field': 'password', 'message': 'size must be between 4 and 100'}], 'params': None}
2021-04-15 09:50:36,093-INFO-my_log.py-python-日志信息:PASS
2021-04-15 09:50:36,094-INFO-my_log.py-python-日志信息:开始执行用例：4--账号错误
2021-04-15 09:50:36,094-INFO-my_log.py-python-日志信息:获取到的请求数据是:{"username": "qwwrty", "password": "password.1"}
2021-04-15 09:50:36,305-INFO-my_log.py-python-日志信息:获取到的结果是：{'AuthenticationException': 'Bad credentials'}
2021-04-15 09:50:36,306-INFO-my_log.py-python-日志信息:PASS
2021-04-15 09:50:36,306-INFO-my_log.py-python-日志信息:开始执行用例：5--账号为空
2021-04-15 09:50:36,307-INFO-my_log.py-python-日志信息:获取到的请求数据是:{"username": "", "password": "password.1"}
2021-04-15 09:50:36,396-INFO-my_log.py-python-日志信息:获取到的结果是：{'message': 'error.validation', 'description': None, 'fieldErrors': [{'objectName': 'loginVM', 'field': 'username', 'message': 'size must be between 1 and 50'}], 'params': None}
2021-04-15 09:50:36,397-INFO-my_log.py-python-日志信息:PASS
2021-04-15 09:50:36,398-INFO-my_log.py-python-日志信息:开始执行用例：6--账号密码全错
2021-04-15 09:50:36,398-INFO-my_log.py-python-日志信息:获取到的请求数据是:{"username": "qwwrty", "password": "password.3"}
2021-04-15 09:50:36,609-INFO-my_log.py-python-日志信息:获取到的结果是：{'AuthenticationException': 'Bad credentials'}
2021-04-15 09:50:36,610-INFO-my_log.py-python-日志信息:PASS
2021-04-15 09:50:36,611-INFO-my_log.py-python-日志信息:开始执行用例：7--账号密码全空
2021-04-15 09:50:36,612-INFO-my_log.py-python-日志信息:获取到的请求数据是:{"username": "", "password": ""}
2021-04-15 09:50:36,709-INFO-my_log.py-python-日志信息:获取到的结果是：{'message': 'error.validation', 'description': None, 'fieldErrors': [{'objectName': 'loginVM', 'field': 'username', 'message': 'size must be between 1 and 50'}, {'objectName': 'loginVM', 'field': 'password', 'message': 'size must be between 4 and 100'}], 'params': None}
2021-04-15 09:50:36,710-INFO-my_log.py-python-日志信息:PASS
2021-04-16 09:40:52,947-INFO-my_log.py-python-日志信息:开始执行用例：1--正常登录
2021-04-16 09:40:52,948-INFO-my_log.py-python-日志信息:获取到的请求数据是:{"username": "m", "password": "password.1"}
2021-04-16 09:40:53,246-INFO-my_log.py-python-日志信息:获取到的结果是：{'id_token': 'eyJhbGciOiJIUzUxMiJ9.eyJzdWIiOiJtIiwiYXV0aCI6IlJPTEVfQklPSU5GTyxST0xFX0NPTUJJTkVEX1RIRVJBUFlfUixST0xFX0NPTUJJTkVEX1RIRVJBUFlfVyxST0xFX0NSLFJPTEVfREVBVEhfQVBQUk9WRV9BLFJPTEVfREVBVEhfQVBQUk9WRV9SLFJPTEVfRElTRUFTRV9DT1VSU0VfQSxST0xFX0RJU0VBU0VfQ09VUlNFX1IsUk9MRV9ESVNFQVNFX0NPVVJTRV9TWU5DLFJPTEVfRElTRUFTRV9DT1VSU0VfVyxST0xFX0RJX0NVU1RPTUVSX1IsUk9MRV9ESV9DVVNUT01FUl9XLFJPTEVfRElfTUVESUNBTF9SRVNVTFRfUixST0xFX0RPQ1RPUl9SLFJPTEVfRE9DVE9SX1csUk9MRV9EUlVHX0RJQ1RJT05BUllfUixST0xFX0RSVUdfRElDVElPTkFSWV9XLFJPTEVfRU1QTE9ZRUVfVyxST0xFX0ZJTkFOQ0lBTF9SRVBPUlQsUk9MRV9GSU5BTkNJQUxfU0VUVExFTUVOVF9DLFJPTEVfRklOQU5DSUFMX1NFVFRMRU1FTlRfUixST0xFX0ZJTkFOQ0lBTF9TRVRUTEVNRU5UX1csUk9MRV9GT0xMT1dfVVBfQVRURU5USU9OX1QsUk9MRV9GT0xMT1dfVVBfQVRURU5USU9OX1csUk9MRV9GT0xMT1dfVVBfUkVDT1JEX1csUk9MRV9IT1NQSVRBTF9DT05GSVJNX0RFQVRIX0FQUFJPVkVfQSxST0xFX0hPU1BJVEFMX0NPTkZJUk1fREVBVEhfQVBQUk9WRV9SLFJPTEVfSE9TUElUQUxfUixST0xFX0hPU1BJVEFMX1csUk9MRV9NQVRFUklBTF9BLFJPTEVfTUFURVJJQUxfUixST0xFX01BVEVSSUFMX1JFUE9SVCxST0xFX01BVEVSSUFMX1csUk9MRV9NRURJQ0FMLFJPTEVfT1JERVJfQSxST0xFX09SREVSX0NBTkNFTCxST0xFX09SREVSX0NMT1NFLFJPTEVfT1JERVJfQ09ORklSTV9SRUNFSVBULFJPTEVfT1JERVJfUixST0xFX09SREVSX1JFRlVORCxST0xFX09SREVSX1csUk9MRV9QQVRJRU5UX0FERFJFU1NfUixST0xFX1BBVElFTlRfQUREUkVTU19XLFJPTEVfUEFUSUVOVF9EQVRBX0lOVEVHUklUWV9DT01QTEVURV9SRVBPUlQsUk9MRV9QQVRJRU5UX1IsUk9MRV9QQVRJRU5UX1JFUE9SVCxST0xFX1BBVElFTlRfVyxST0xFX1BSRV9PUkRFUl9SLFJPTEVfUFJPRFVDVF9SLFJPTEVfUFJPRFVDVF9XLFJPTEVfUFJPRFVDVF9XX0JBU0lDLFJPTEVfUFJPRFVDVF9XX1JFUE9SVF9GSUxFLFJPTEVfUFJPRFVDVF9XX1U4LFJPTEVfUVVBUlRFUl9SRVBPUlRfVyxST0xFX1JFUE9SVF9SLFJPTEVfUkVQT1JUX1csUk9MRV9SRVNFQVJDSF9DT05UUkFDVF9SLFJPTEVfUkVTRUFSQ0hfQ09OVFJBQ1RfVyxST0xFX1JFVklFV19XLFJPTEVfU0FMRSxST0xFX1RFTkFOVF9SLFJPTEVfVEVOQU5UX1csUk9MRV9USU1FTElORV9XLFJPTEVfVFJFQVRNRU5UX1csUk9MRV9VU0VSIiwiZXhwIjoxNjE4NjIzNjUzfQ.39_AXv7yzxfuqQjVE51eeY6fP-Pbpe7_WOXf_wG3OOh_przBruhm7OHaZtCatPm5Fgxl74F1I9Xmf_Zvg9ZNig'}
2021-04-16 09:40:53,247-INFO-my_log.py-python-日志信息:PASS
2021-04-16 09:40:53,248-INFO-my_log.py-python-日志信息:开始执行用例：2--密码错误
2021-04-16 09:40:53,249-INFO-my_log.py-python-日志信息:获取到的请求数据是:{"username": "m", "password": "12345678"}
2021-04-16 09:40:53,464-INFO-my_log.py-python-日志信息:获取到的结果是：{'AuthenticationException': 'Bad credentials'}
2021-04-16 09:40:53,466-INFO-my_log.py-python-日志信息:PASS
2021-04-16 09:40:53,467-INFO-my_log.py-python-日志信息:开始执行用例：3--密码为空
2021-04-16 09:40:53,468-INFO-my_log.py-python-日志信息:获取到的请求数据是:{"username": "m", "password": ""}
2021-04-16 09:40:53,747-INFO-my_log.py-python-日志信息:获取到的结果是：{'message': 'error.validation', 'description': None, 'fieldErrors': [{'objectName': 'loginVM', 'field': 'password', 'message': 'size must be between 4 and 100'}], 'params': None}
2021-04-16 09:40:53,748-INFO-my_log.py-python-日志信息:PASS
2021-04-16 09:40:53,750-INFO-my_log.py-python-日志信息:开始执行用例：4--账号错误
2021-04-16 09:40:53,751-INFO-my_log.py-python-日志信息:获取到的请求数据是:{"username": "qwwrty", "password": "password.1"}
2021-04-16 09:40:53,953-INFO-my_log.py-python-日志信息:获取到的结果是：{'AuthenticationException': 'Bad credentials'}
2021-04-16 09:40:53,954-INFO-my_log.py-python-日志信息:PASS
2021-04-16 09:40:53,956-INFO-my_log.py-python-日志信息:开始执行用例：5--账号为空
2021-04-16 09:40:53,957-INFO-my_log.py-python-日志信息:获取到的请求数据是:{"username": "", "password": "password.1"}
2021-04-16 09:40:54,055-INFO-my_log.py-python-日志信息:获取到的结果是：{'message': 'error.validation', 'description': None, 'fieldErrors': [{'objectName': 'loginVM', 'field': 'username', 'message': 'size must be between 1 and 50'}], 'params': None}
2021-04-16 09:40:54,056-INFO-my_log.py-python-日志信息:PASS
2021-04-16 09:40:54,056-INFO-my_log.py-python-日志信息:开始执行用例：6--账号密码全错
2021-04-16 09:40:54,057-INFO-my_log.py-python-日志信息:获取到的请求数据是:{"username": "qwwrty", "password": "password.3"}
2021-04-16 09:40:54,271-INFO-my_log.py-python-日志信息:获取到的结果是：{'AuthenticationException': 'Bad credentials'}
2021-04-16 09:40:54,272-INFO-my_log.py-python-日志信息:PASS
2021-04-16 09:40:54,273-INFO-my_log.py-python-日志信息:开始执行用例：7--账号密码全空
2021-04-16 09:40:54,274-INFO-my_log.py-python-日志信息:获取到的请求数据是:{"username": "", "password": ""}
2021-04-16 09:40:54,369-INFO-my_log.py-python-日志信息:获取到的结果是：{'message': 'error.validation', 'description': None, 'fieldErrors': [{'objectName': 'loginVM', 'field': 'password', 'message': 'size must be between 4 and 100'}, {'objectName': 'loginVM', 'field': 'username', 'message': 'size must be between 1 and 50'}], 'params': None}
2021-04-16 09:40:54,370-INFO-my_log.py-python-日志信息:PASS
2021-04-16 14:19:54,654-INFO-my_log.py-python-日志信息:开始执行用例：1--正常登录
2021-04-16 14:19:54,667-INFO-my_log.py-python-日志信息:获取到的请求数据是:{"username": "m", "password": "password.1"}
2021-04-16 14:19:54,996-INFO-my_log.py-python-日志信息:获取到的结果是：{'id_token': 'eyJhbGciOiJIUzUxMiJ9.eyJzdWIiOiJtIiwiYXV0aCI6IlJPTEVfQklPSU5GTyxST0xFX0NPTUJJTkVEX1RIRVJBUFlfUixST0xFX0NPTUJJTkVEX1RIRVJBUFlfVyxST0xFX0NSLFJPTEVfREVBVEhfQVBQUk9WRV9BLFJPTEVfREVBVEhfQVBQUk9WRV9SLFJPTEVfRElTRUFTRV9DT1VSU0VfQSxST0xFX0RJU0VBU0VfQ09VUlNFX1IsUk9MRV9ESVNFQVNFX0NPVVJTRV9TWU5DLFJPTEVfRElTRUFTRV9DT1VSU0VfVyxST0xFX0RJX0NVU1RPTUVSX1IsUk9MRV9ESV9DVVNUT01FUl9XLFJPTEVfRElfTUVESUNBTF9SRVNVTFRfUixST0xFX0RPQ1RPUl9SLFJPTEVfRE9DVE9SX1csUk9MRV9EUlVHX0RJQ1RJT05BUllfUixST0xFX0RSVUdfRElDVElPTkFSWV9XLFJPTEVfRU1QTE9ZRUVfVyxST0xFX0ZJTkFOQ0lBTF9SRVBPUlQsUk9MRV9GSU5BTkNJQUxfU0VUVExFTUVOVF9DLFJPTEVfRklOQU5DSUFMX1NFVFRMRU1FTlRfUixST0xFX0ZJTkFOQ0lBTF9TRVRUTEVNRU5UX1csUk9MRV9GT0xMT1dfVVBfQVRURU5USU9OX1QsUk9MRV9GT0xMT1dfVVBfQVRURU5USU9OX1csUk9MRV9GT0xMT1dfVVBfUkVDT1JEX1csUk9MRV9IT1NQSVRBTF9DT05GSVJNX0RFQVRIX0FQUFJPVkVfQSxST0xFX0hPU1BJVEFMX0NPTkZJUk1fREVBVEhfQVBQUk9WRV9SLFJPTEVfSE9TUElUQUxfUixST0xFX0hPU1BJVEFMX1csUk9MRV9NQVRFUklBTF9BLFJPTEVfTUFURVJJQUxfUixST0xFX01BVEVSSUFMX1JFUE9SVCxST0xFX01BVEVSSUFMX1csUk9MRV9NRURJQ0FMLFJPTEVfT1JERVJfQSxST0xFX09SREVSX0NBTkNFTCxST0xFX09SREVSX0NMT1NFLFJPTEVfT1JERVJfQ09ORklSTV9SRUNFSVBULFJPTEVfT1JERVJfUixST0xFX09SREVSX1JFRlVORCxST0xFX09SREVSX1csUk9MRV9QQVRJRU5UX0FERFJFU1NfUixST0xFX1BBVElFTlRfQUREUkVTU19XLFJPTEVfUEFUSUVOVF9EQVRBX0lOVEVHUklUWV9DT01QTEVURV9SRVBPUlQsUk9MRV9QQVRJRU5UX1IsUk9MRV9QQVRJRU5UX1JFUE9SVCxST0xFX1BBVElFTlRfVyxST0xFX1BSRV9PUkRFUl9SLFJPTEVfUFJPRFVDVF9SLFJPTEVfUFJPRFVDVF9XLFJPTEVfUFJPRFVDVF9XX0JBU0lDLFJPTEVfUFJPRFVDVF9XX1JFUE9SVF9GSUxFLFJPTEVfUFJPRFVDVF9XX1U4LFJPTEVfUVVBUlRFUl9SRVBPUlRfVyxST0xFX1JFUE9SVF9SLFJPTEVfUkVQT1JUX1csUk9MRV9SRVNFQVJDSF9DT05UUkFDVF9SLFJPTEVfUkVTRUFSQ0hfQ09OVFJBQ1RfVyxST0xFX1JFVklFV19XLFJPTEVfU0FMRSxST0xFX1RFTkFOVF9SLFJPTEVfVEVOQU5UX1csUk9MRV9USU1FTElORV9XLFJPTEVfVFJFQVRNRU5UX1csUk9MRV9VU0VSIiwiZXhwIjoxNjE4NjQwMzk0fQ.Cfz6qxDHjJdLiTTdRDSbutR82Q_NBqNW1PCT3siNLPqjY5_50R0AOfQMsd6VUwUevc_LzSbouT0Zel_mh3lPYA'}
2021-04-16 14:19:54,996-INFO-my_log.py-python-日志信息:PASS
2021-04-16 14:19:54,999-INFO-my_log.py-python-日志信息:开始执行用例：2--密码错误
2021-04-16 14:19:55,000-INFO-my_log.py-python-日志信息:获取到的请求数据是:{"username": "m", "password": "12345678"}
2021-04-16 14:19:55,369-INFO-my_log.py-python-日志信息:获取到的结果是：{'AuthenticationException': 'Bad credentials'}
2021-04-16 14:19:55,371-INFO-my_log.py-python-日志信息:PASS
2021-04-16 14:19:55,372-INFO-my_log.py-python-日志信息:开始执行用例：3--密码为空
2021-04-16 14:19:55,372-INFO-my_log.py-python-日志信息:获取到的请求数据是:{"username": "m", "password": ""}
2021-04-16 14:19:55,496-INFO-my_log.py-python-日志信息:获取到的结果是：{'message': 'error.validation', 'description': None, 'fieldErrors': [{'objectName': 'loginVM', 'field': 'password', 'message': 'size must be between 4 and 100'}], 'params': None}
2021-04-16 14:19:55,496-INFO-my_log.py-python-日志信息:PASS
2021-04-16 14:19:55,499-INFO-my_log.py-python-日志信息:开始执行用例：4--账号错误
2021-04-16 14:19:55,500-INFO-my_log.py-python-日志信息:获取到的请求数据是:{"username": "qwwrty", "password": "password.1"}
2021-04-16 14:19:55,702-INFO-my_log.py-python-日志信息:获取到的结果是：{'AuthenticationException': 'Bad credentials'}
2021-04-16 14:19:55,703-INFO-my_log.py-python-日志信息:PASS
2021-04-16 14:19:55,704-INFO-my_log.py-python-日志信息:开始执行用例：5--账号为空
2021-04-16 14:19:55,705-INFO-my_log.py-python-日志信息:获取到的请求数据是:{"username": "", "password": "password.1"}
2021-04-16 14:19:55,799-INFO-my_log.py-python-日志信息:获取到的结果是：{'message': 'error.validation', 'description': None, 'fieldErrors': [{'objectName': 'loginVM', 'field': 'username', 'message': 'size must be between 1 and 50'}], 'params': None}
2021-04-16 14:19:55,800-INFO-my_log.py-python-日志信息:PASS
2021-04-16 14:19:55,802-INFO-my_log.py-python-日志信息:开始执行用例：6--账号密码全错
2021-04-16 14:19:55,803-INFO-my_log.py-python-日志信息:获取到的请求数据是:{"username": "qwwrty", "password": "password.3"}
2021-04-16 14:19:56,019-INFO-my_log.py-python-日志信息:获取到的结果是：{'AuthenticationException': 'Bad credentials'}
2021-04-16 14:19:56,019-INFO-my_log.py-python-日志信息:PASS
2021-04-16 14:19:56,020-INFO-my_log.py-python-日志信息:开始执行用例：7--账号密码全空
2021-04-16 14:19:56,022-INFO-my_log.py-python-日志信息:获取到的请求数据是:{"username": "", "password": ""}
2021-04-16 14:19:56,121-INFO-my_log.py-python-日志信息:获取到的结果是：{'message': 'error.validation', 'description': None, 'fieldErrors': [{'objectName': 'loginVM', 'field': 'password', 'message': 'size must be between 4 and 100'}, {'objectName': 'loginVM', 'field': 'username', 'message': 'size must be between 1 and 50'}], 'params': None}
2021-04-16 14:19:56,123-INFO-my_log.py-python-日志信息:PASS
